Workbook

Sheet Read Me
A1: SparshaGuard — parameter sources
A3: Purpose | B3: Every value taken from a paper for the SparshaGuard simulation, with its full reference, and every parameter the model uses with where it came from.
A4: Project folder | B4: D:\SPARSHA (model: sg_model.py; notes: docs\parameter_sources.md, docs\new_findings_pending.md)
A5: Last updated | B5: 2026-10-11
A7: Sheets
A8: Values from Papers | B8: The log: one row per value, with source, location in the source and status.
A9: Sources | B9: Full reference and link for each source ID.
A10: Model v0.2 Params | B10: Each parameter in sg_model.py, the value used, and its tag and sources.
A11: Still Estimated | B11: Values with no published source yet, and how Gate 1 should measure them.
A13: Adding a value | B13: Add a row at the bottom of 'Values from Papers'. Fill Category to Location, pick a Status from the drop-down, and use a Source ID listed on 'Sources' (add the source there first if it's new). The short source name fills in by itself.
A15: Counts (live)
A16: Sources | B16: =COUNTA(Sources!$A$4:$A$500) -> 16
A17: Values logged | B17: =COUNTA('Values from Papers'!$A$5:$A$1000) -> 106
A18: In model v0.2 | B18: =COUNTIF('Values from Papers'!$J:$J,"In model v0.2") -> 34
A19: Pending integration | B19: =COUNTIF('Values from Papers'!$J:$J,"Pending integration") -> 25
A20: Benchmark only | B20: =COUNTIF('Values from Papers'!$J:$J,"Benchmark only") -> 11
A21: Context only | B21: =COUNTIF('Values from Papers'!$J:$J,"Context only") -> 36
A22: Model parameters | B22: =COUNTA('Model v0.2 Params'!$A$4:$A$500) -> 35
A23: …of which still estimated (tag E) | B23: =COUNTIF('Model v0.2 Params'!$E$4:$E$500,"E") -> 14

Sheet Values from Papers
A1: Values from papers
A2: One row per value taken from a source. Status colours: green = in model v0.2, yellow = found, awaiting integration, blue = accuracy benchmark, grey = context only.
A4: ID | B4: Category | C4: Parameter | D4: Value | E4: Unit | F4: Conditions / context | G4: Source ID | H4: Source (short) | I4: Location in source | J4: Status | K4: How it's used in the model | L4: Notes
A5: V001 | B5: Sweep | C5: Sweep range | D5: 1 kHz – 3.5 MHz | E5: Hz | F5: Swept sine, AD5932 generator | G5: S1 | H5: =IFERROR(INDEX(Sources!$B:$B,MATCH(G5,Sources!$A:$A,0)),"") -> Sato et al. 2012 (Touché) | I5: Hardware section | J5: In model v0.2 | K5: Sweep grid 1 kHz – 3.4835 MHz
A6: V002 | B6: Sweep | C6: Frequency step | D6: 17.5 | E6: kHz | G6: S1 | H6: =IFERROR(INDEX(Sources!$B:$B,MATCH(G6,Sources!$A:$A,0)),"") -> Sato et al. 2012 (Touché) | I6: Hardware section | J6: In model v0.2 | K6: 17.5 kHz
A7: V003 | B7: Sweep | C7: Steps per sweep | D7: 200 | E7: count | G7: S1 | H7: =IFERROR(INDEX(Sources!$B:$B,MATCH(G7,Sources!$A:$A,0)),"") -> Sato et al. 2012 (Touché) | I7: Hardware section | J7: In model v0.2 | K7: 200
A8: V004 | B8: Sweep | C8: Excitation amplitude | D8: 6.6 | E8: V p-p | F8: After amplification | G8: S1 | H8: =IFERROR(INDEX(Sources!$B:$B,MATCH(G8,Sources!$A:$A,0)),"") -> Sato et al. 2012 (Touché) | I8: Hardware section | J8: Context only | K8: Results in % of full scale; cancels out
A9: V005 | B9: Sweep | C9: Sweep duration | D9: 33 | E9: ms | F9: ~33 Hz update; ~100 Hz if only high band swept | G9: S1 | H9: =IFERROR(INDEX(Sources!$B:$B,MATCH(G9,Sources!$A:$A,0)),"") -> Sato et al. 2012 (Touché) | I9: Hardware section | J9: In model v0.2 | K9: Basis of 5 frames/s pipeline
A10: V006 | B10: Circuit | C10: Bias inductor Lb | D10: ~100 | E10: mH | F10: Tunes sensitivity at lower frequencies | G10: S1 | H10: =IFERROR(INDEX(Sources!$B:$B,MATCH(G10,Sources!$A:$A,0)),"") -> Sato et al. 2012 (Touché) | I10: Hardware section | J10: Context only | K10: Model uses Arduino version 10 mH (S3)
A11: V007 | B11: Measurement | C11: Measured quantity | D11: Amplitude only | E11: - | F11: Envelope detector; phase not measured | G11: S1 | H11: =IFERROR(INDEX(Sources!$B:$B,MATCH(G11,Sources!$A:$A,0)),"") -> Sato et al. 2012 (Touché) | I11: Hardware section | J11: In model v0.2 | K11: Amplitude-only score and classifier
A12: V008 | B12: Measurement | C12: ADC resolution | D12: 12 | E12: bit | F12: Max 200 kHz sampling | G12: S1 | H12: =IFERROR(INDEX(Sources!$B:$B,MATCH(G12,Sources!$A:$A,0)),"") -> Sato et al. 2012 (Touché) | I12: Hardware section | J12: In model v0.2 | K12: Basis of noise estimate
A13: V009 | B13: Device | C13: Sensor board size / mass | D13: 36 × 36 × 5.5 mm, 13.8 g | E13: - | G13: S1 | H13: =IFERROR(INDEX(Sources!$B:$B,MATCH(G13,Sources!$A:$A,0)),"") -> Sato et al. 2012 (Touché) | I13: Hardware section | J13: Context only
A14: V010 | B14: Body | C14: Trunk internal resistance | D14: ~100 | E14: Ω | F14: Average | G14: S1 | H14: =IFERROR(INDEX(Sources!$B:$B,MATCH(G14,Sources!$A:$A,0)),"") -> Sato et al. 2012 (Touché) | I14: Body-as-sensor section | J14: In model v0.2 | K14: +100 Ω added to limb resistance
A15: V011 | B15: Skin | C15: Dry intact skin resistance | D15: ~1 | E15: MΩ | G15: S1 | H15: =IFERROR(INDEX(Sources!$B:$B,MATCH(G15,Sources!$A:$A,0)),"") -> Sato et al. 2012 (Touché) | I15: Body-as-sensor section | J15: In model v0.2 | K15: Dry end of hydration range | L15: Contact area not stated
A16: V012 | B16: Classifier | C16: Classifier | D16: SVM (Weka SMO), polynomial kernel, C = 2.0 | E16: - | F16: Features: 200 raw + derivatives + minima | G16: S1 | H16: =IFERROR(INDEX(Sources!$B:$B,MATCH(G16,Sources!$A:$A,0)),"") -> Sato et al. 2012 (Touché) | I16: Classification section | J16: In model v0.2 | K16: SVM (RBF) and random forest
A17: V013 | B17: Accuracy | C17: On-body (wrist-to-wrist), 5 gestures, per user | D17: 84 | E17: % | F17: SD 11.4% | G17: S1 | H17: =IFERROR(INDEX(Sources!$B:$B,MATCH(G17,Sources!$A:$A,0)),"") -> Sato et al. 2012 (Touché) | I17: Study 4 | J17: Benchmark only | L17: Closest to a wrist-worn sensor
A18: V014 | B18: Accuracy | C18: On-body, 5 gestures, walk-up | D18: 52.9 | E18: % | F18: SD 13.8%; no per-user training | G18: S1 | H18: =IFERROR(INDEX(Sources!$B:$B,MATCH(G18,Sources!$A:$A,0)),"") -> Sato et al. 2012 (Touché) | I18: Study 4 | J18: Benchmark only
A19: V015 | B19: Accuracy | C19: On-body, 3 gestures, walk-up | D19: 87.1 | E19: % | F19: SD 12.5% | G19: S1 | H19: =IFERROR(INDEX(Sources!$B:$B,MATCH(G19,Sources!$A:$A,0)),"") -> Sato et al. 2012 (Touché) | I19: Study 4 | J19: Benchmark only
A20: V016 | B20: Accuracy | C20: Mobile mockup (ungrounded), 5 gestures | D20: 93.3 | E20: % | F20: SD 6.2%; walk-up 76.1% | G20: S1 | H20: =IFERROR(INDEX(Sources!$B:$B,MATCH(G20,Sources!$A:$A,0)),"") -> Sato et al. 2012 (Touché) | I20: Study 3 | J20: Benchmark only | L20: Authors call it the hardest setup
A21: V017 | B21: Accuracy | C21: Doorknob (grounded), 5 gestures | D21: 96.7 | E21: % | F21: SD 5.6% | G21: S1 | H21: =IFERROR(INDEX(Sources!$B:$B,MATCH(G21,Sources!$A:$A,0)),"") -> Sato et al. 2012 (Touché) | I21: Study 1 | J21: Benchmark only
A22: V018 | B22: Accuracy | C22: Table (body configuration), 7 gestures | D22: 92.6 | E22: % | F22: SD 9.4% | G22: S1 | H22: =IFERROR(INDEX(Sources!$B:$B,MATCH(G22,Sources!$A:$A,0)),"") -> Sato et al. 2012 (Touché) | I22: Study 2 | J22: Benchmark only
A23: V019 | B23: Accuracy | C23: Liquid (fish tank), 5 gestures | D23: 99.8 | E23: % | F23: SD 0.8% | G23: S1 | H23: =IFERROR(INDEX(Sources!$B:$B,MATCH(G23,Sources!$A:$A,0)),"") -> Sato et al. 2012 (Touché) | I23: Study 5 | J23: Benchmark only | L23: Source of the '99%' headline
A24: V020 | B24: Accuracy | C24: Participants | D24: 12 | E24: people | F24: 9 male, 3 female (studies 1-4) | G24: S1 | H24: =IFERROR(INDEX(Sources!$B:$B,MATCH(G24,Sources!$A:$A,0)),"") -> Sato et al. 2012 (Touché) | I24: Studies | J24: Benchmark only
A25: V021 | B25: Sweep | C25: Sweep range / steps | D25: 1 kHz – 3.5 MHz, 200 steps | E25: - | G25: S2 | H25: =IFERROR(INDEX(Sources!$B:$B,MATCH(G25,Sources!$A:$A,0)),"") -> Harrison et al. 2012 (Cap. Fingerprinting) | I25: Implementation | J25: In model v0.2 | K25: Same as S1
A26: V022 | B26: Safety | C26: Current through body | D26: < 0.5 | E26: mA | F26: 6.6 V p-p sine | G26: S2 | H26: =IFERROR(INDEX(Sources!$B:$B,MATCH(G26,Sources!$A:$A,0)),"") -> Harrison et al. 2012 (Cap. Fingerprinting) | I26: Implementation | J26: Context only | L26: Described as safe
A27: V023 | B27: Accuracy | C27: User differentiation, 8 s training | D27: 97.3 | E27: % | F27: SD 5.9%; 11 people, 55 pairings | G27: S2 | H27: =IFERROR(INDEX(Sources!$B:$B,MATCH(G27,Sources!$A:$A,0)),"") -> Harrison et al. 2012 (Cap. Fingerprinting) | I27: Results | J27: Benchmark only
A28: V024 | B28: Accuracy | C28: User differentiation, 0.1 s training | D28: 84.5 | E28: % | F28: SD 18.9% | G28: S2 | H28: =IFERROR(INDEX(Sources!$B:$B,MATCH(G28,Sources!$A:$A,0)),"") -> Harrison et al. 2012 (Cap. Fingerprinting) | I28: Results | J28: Benchmark only
A29: V025 | B29: Accuracy | C29: Best single frequency (753.5 kHz) | D29: 87.3 | E29: % | F29: vs 97.3% for full sweep | G29: S2 | H29: =IFERROR(INDEX(Sources!$B:$B,MATCH(G29,Sources!$A:$A,0)),"") -> Harrison et al. 2012 (Cap. Fingerprinting) | I29: Results | J29: Benchmark only | K29: Supports using the full sweep
A30: V026 | B30: Body | C30: Bone resistivity | D30: 45 → 90 | E30: Ω·m | F30: 1 kHz → 1 MHz (cited from their ref 11) | G30: S2 | H30: =IFERROR(INDEX(Sources!$B:$B,MATCH(G30,Sources!$A:$A,0)),"") -> Harrison et al. 2012 (Cap. Fingerprinting) | I30: Background | J30: Context only
A31: V027 | B31: Drift | C31: Calibration drift over a day | D31: Qualitative | E31: - | F31: Temperature, humidity, hydration; re-login needed after hours | G31: S2 | H31: =IFERROR(INDEX(Sources!$B:$B,MATCH(G31,Sources!$A:$A,0)),"") -> Harrison et al. 2012 (Cap. Fingerprinting) | I31: Discussion | J31: In model v0.2 | K31: Adaptive baseline in pipeline | L31: No numbers given
A32: V028 | B32: Circuit | C32: Series resistor R1 | D32: 10 | E32: kΩ | F32: Arduino SFCS circuit, Fig. 2 | G32: S3 | H32: =IFERROR(INDEX(Sources!$B:$B,MATCH(G32,Sources!$A:$A,0)),"") -> Honigman et al. 2014 (Arduino Touché) | I32: Fig. 2 | J32: In model v0.2 | K32: Rs = 10 kΩ
A33: V029 | B33: Circuit | C33: Inductor L1 | D33: 10 | E33: mH | G33: S3 | H33: =IFERROR(INDEX(Sources!$B:$B,MATCH(G33,Sources!$A:$A,0)),"") -> Honigman et al. 2014 (Arduino Touché) | I33: Fig. 2 | J33: In model v0.2 | K33: L = 10 mH ±5%
A34: V030 | B34: Circuit | C34: Tank capacitor C2 | D34: 100 | E34: pF | F34: Listed as 0.1 nF | G34: S3 | H34: =IFERROR(INDEX(Sources!$B:$B,MATCH(G34,Sources!$A:$A,0)),"") -> Honigman et al. 2014 (Arduino Touché) | I34: Fig. 2 | J34: In model v0.2 | K34: Ctank = 100 pF ±5%
A35: V031 | B35: Circuit | C35: Envelope detector | D35: 1N4148, 10 nF, 1 MΩ, 3.3 kΩ | E35: - | G35: S3 | H35: =IFERROR(INDEX(Sources!$B:$B,MATCH(G35,Sources!$A:$A,0)),"") -> Honigman et al. 2014 (Arduino Touché) | I35: Fig. 2 | J35: Context only
A36: V032 | B36: Sweep | C36: Max frequencies per sweep (Arduino library) | D36: 198 | E36: count | G36: S3 | H36: =IFERROR(INDEX(Sources!$B:$B,MATCH(G36,Sources!$A:$A,0)),"") -> Honigman et al. 2014 (Arduino Touché) | I36: Text | J36: Context only
A37: V033 | B37: Body | C37: Body capacitance: polymer shoes, linoleum | D37: 160–170 | E37: pF | F37: AC bridge, 1 kHz | G37: S4 | H37: =IFERROR(INDEX(Sources!$B:$B,MATCH(G37,Sources!$A:$A,0)),"") -> Jonassen 1998 | I37: Table 1 | J37: In model v0.2 | K37: Street shoes 110–170 pF
A38: V034 | B38: Body | C38: Body capacitance: polymer shoes, asphalt | D38: 110 | E38: pF | F38: AC bridge | G38: S4 | H38: =IFERROR(INDEX(Sources!$B:$B,MATCH(G38,Sources!$A:$A,0)),"") -> Jonassen 1998 | I38: Table 1 | J38: In model v0.2 | K38: Street shoes 110–170 pF
A39: V035 | B39: Body | C39: Body capacitance: leather shoes, asphalt | D39: 115 | E39: pF | F39: AC bridge | G39: S4 | H39: =IFERROR(INDEX(Sources!$B:$B,MATCH(G39,Sources!$A:$A,0)),"") -> Jonassen 1998 | I39: Table 2 | J39: In model v0.2 | K39: Street shoes 110–170 pF
A40: V036 | B40: Body | C40: Body capacitance: barefoot, linoleum | D40: 250 | E40: pF | F40: AC bridge | G40: S4 | H40: =IFERROR(INDEX(Sources!$B:$B,MATCH(G40,Sources!$A:$A,0)),"") -> Jonassen 1998 | I40: Table 1 | J40: In model v0.2 | K40: Barefoot 185–250 pF
A41: V037 | B41: Body | C41: Body capacitance: barefoot, asphalt | D41: 185 | E41: pF | F41: AC bridge | G41: S4 | H41: =IFERROR(INDEX(Sources!$B:$B,MATCH(G41,Sources!$A:$A,0)),"") -> Jonassen 1998 | I41: Table 1 | J41: In model v0.2 | K41: Barefoot 185–250 pF
...

Sheet Sources
A1: Sources
A2: Full reference for every source ID used in this workbook and in sg_model.py.
A3: Source ID | B3: Short name | C3: Authors | D3: Title | E3: Venue | F3: Year | G3: Type | H3: Proposal ref | I3: Link | J3: Accessed | K3: Notes | L3: Values logged
A4: S1 | B4: Sato et al. 2012 (Touché) | C4: M. Sato, I. Poupyrev, C. Harrison | D4: Touché: Enhancing Touch Interaction on Humans, Screens, Liquids, and Everyday Objects | E4: Proc. ACM CHI 2012 | F4: 2012 | G4: Peer-reviewed conference | H4: Ref 5 | I4: https://la.disneyresearch.com/wp-content/uploads/touchechi20121.pdf | J4: 2026-10-11 | K4: Core method of the proposal | L4: =COUNTIF('Values from Papers'!$G:$G,A4) -> 20
A5: S2 | B5: Harrison et al. 2012 (Cap. Fingerprinting) | C5: C. Harrison, M. Sato, I. Poupyrev | D5: Capacitive Fingerprinting: Exploring User Differentiation by Sensing Electrical Properties of the Human Body | E5: Proc. ACM UIST 2012 | F5: 2012 | G5: Peer-reviewed conference | H5: Ref 6 | I5: https://la.disneyresearch.com/wp-content/uploads/capacitive-fingerprintingcameraready1.pdf | J5: 2026-10-11 | L5: =COUNTIF('Values from Papers'!$G:$G,A5) -> 7
A6: S3 | B6: Honigman et al. 2014 (Arduino Touché) | C6: N. Honigman et al. | D6: Techniques in Swept Frequency Capacitive Sensing: An Open Source Approach | E6: Proc. NIME 2014 | F6: 2014 | G6: Peer-reviewed conference | H6: - | I6: https://nime.org/proceedings/2014/nime2014_515.pdf | J6: 2026-10-11 | K6: Arduino Touché circuit; component list also at https://github.com/sofian/touche | L6: =COUNTIF('Values from Papers'!$G:$G,A6) -> 5
A7: S4 | B7: Jonassen 1998 | C7: N. M. Jonassen | D7: Human Body Capacitance: Static or Dynamic Concept? | E7: EOS/ESD Symposium Proceedings, pp. 111-117 | F7: 1998 | G7: Peer-reviewed conference | H7: - | I7: https://backend.orbit.dtu.dk/ws/files/4363898/Jonassen.pdf | J7: 2026-10-11 | K7: Scanned text; some table cells hard to read | L7: =COUNTIF('Values from Papers'!$G:$G,A7) -> 11
A8: S5 | B8: Maity et al. 2019 | C8: S. Maity, M. He, M. Nath, D. Das, B. Chatterjee, S. Sen | D8: Bio-Physical Modeling, Characterization and Optimization of Electro-Quasistatic Human Body Communication | E8: IEEE Transactions on Biomedical Engineering | F8: 2019 | G8: Peer-reviewed journal | H8: - | I8: https://arxiv.org/pdf/1805.05200.pdf | J8: 2026-10-11 | K8: arXiv version read | L8: =COUNTIF('Values from Papers'!$G:$G,A8) -> 10
A9: S6 | B9: Martinsen et al. 1997 | C9: Ø. G. Martinsen, S. Grimnes, O. Sveen | D9: Dielectric properties of some keratinised tissues. Part 1: Stratum corneum and nail in situ | E9: Medical & Biological Engineering & Computing 35, 172-176 | F9: 1997 | G9: Peer-reviewed journal | H9: - | I9: https://mn.uio.no/fysikk/english/research/projects/bioimpedance/publications/papers/blemme.pdf | J9: 2026-10-11 | L9: =COUNTIF('Values from Papers'!$G:$G,A9) -> 5
A10: S7 | B10: Ng & Reaz 2017 | C10: C. L. Ng, M. B. I. Reaz | D10: Characterization of Textile-Insulated Capacitive Biosensors | E10: Sensors 17(3), 574 | F10: 2017 | G10: Peer-reviewed journal | H10: - | I10: https://doi.org/10.3390/s17030574 | J10: 2026-10-11 | L10: =COUNTIF('Values from Papers'!$G:$G,A10) -> 6
A11: S8 | B11: Avlani et al. 2020 | C11: S. Avlani, M. Nath, S. Maity, S. Sen | D11: A 100KHz-1GHz Termination-dependent Human Body Communication Channel Measurement using Miniaturized Wearable Devices | E11: Proc. DATE 2020, pp. 651-653 | F11: 2020 | G11: Peer-reviewed conference | H11: - | I11: https://par.nsf.gov/servlets/purl/10249175 | J11: 2026-10-11 | L11: =COUNTIF('Values from Papers'!$G:$G,A11) -> 2
A12: S9 | B12: Capacitive sensing survey 2024 | C12: (survey) | D12: Body-Area Capacitive or Electric Field Sensing for Human Activity Recognition and Human-Computer Interaction: A Comprehensive Survey | E12: arXiv:2401.06000 | F12: 2024 | G12: Preprint (survey) | H12: - | I12: https://arxiv.org/abs/2401.06000 | J12: 2026-10-11 | K12: Authors not recorded in this log | L12: =COUNTIF('Values from Papers'!$G:$G,A12) -> 2
A13: S10 | B13: Goyal et al. 2022 | C13: K. Goyal, D. A. Borkholder, S. W. Day | D13: Dependence of Skin-Electrode Contact Impedance on Material and Skin Hydration | E13: Sensors 22(21), 8510 | F13: 2022 | G13: Peer-reviewed journal | H13: - | I13: https://www.mdpi.com/1424-8220/22/21/8510 | J13: 2026-10-11 | K13: PMC9656728 | L13: =COUNTIF('Values from Papers'!$G:$G,A13) -> 10
A14: S11 | B14: Datta et al. 2020 | C14: A. Datta, M. Nath, D. Yang, S. Sen | D14: Advanced Biophysical Model to Capture Channel Variability for EQS Capacitive HBC | E14: arXiv:2010.15339 | F14: 2020 | G14: Preprint | H14: - | I14: https://arxiv.org/pdf/2010.15339 | J14: 2026-10-11 | L14: =COUNTIF('Values from Papers'!$G:$G,A14) -> 7
A15: S12 | B15: Nath et al. 2021 | C15: M. Nath et al. (S. Sen group, Purdue) | D15: Inter-Body Coupling in Electro-Quasistatic Human Body Communication: Theory and Analysis of Security and Interference Properties | E15: Scientific Reports | F15: 2021 | G15: Peer-reviewed journal | H15: - | I15: https://arxiv.org/pdf/2003.13329 | J15: 2026-10-11 | K15: arXiv version read; full author list not recorded | L15: =COUNTIF('Values from Papers'!$G:$G,A15) -> 3
A16: S13 | B16: Agarwal & Sahu 2010 | C16: P. Agarwal, S. Sahu | D16: Determination of hand and palm area as a ratio of body surface area in Indian population | E16: Indian Journal of Plastic Surgery 43(1) | F16: 2010 | G16: Peer-reviewed journal | H16: - | I16: https://www.thieme-connect.de/products/ejournals/pdf/10.1055/s-0039-1699403.pdf | J16: 2026-10-11 | L16: =COUNTIF('Values from Papers'!$G:$G,A16) -> 5
A17: S14 | B17: TI SNOA926 2015 | C17: Texas Instruments | D17: Capacitive Sensing: Ins and Outs of Active Shielding (SNOA926A) | E17: Application report | F17: 2015 | G17: Manufacturer app note | H17: - | I17: https://www.ti.com/lit/pdf/SNOA926 | J17: 2026-10-11 | K17: Table 1 headers misaligned in source; reference column inferred | L17: =COUNTIF('Values from Papers'!$G:$G,A17) -> 5
A18: S15 | B18: Hackaday ADC test | C18: Hackaday.io project | D18: ADC performance: Arduino vs ESP32 vs ADS1115 | E18: Hackaday.io | F18: n.d. | G18: Hobby measurement (weak) | H18: - | I18: https://hackaday.io/project/205380-adc-performance-arduino-vs-esp32-vs-ads1115 | J18: 2026-10-11 | K18: Doesn't state whether figures are std. dev. or peak-to-peak | L18: =COUNTIF('Values from Papers'!$G:$G,A18) -> 3
A19: S16 | B19: Espressif ADC blog 2025 | C19: Espressif Systems | D19: ADC performance (developer blog) | E19: developer.espressif.com | F19: 2025 | G19: Manufacturer documentation | H19: - | I19: https://developer.espressif.com/blog/2025/08/adc-performance/ | J19: 2026-10-11 | L19: =COUNTIF('Values from Papers'!$G:$G,A19) -> 5

Sheet Model v0.2 Params
A1: Parameters used by simulation v0.2
A2: Tag: S = published source, G = geometry calculation, D = our design choice, E = estimate (no source yet).
A3: Parameter | B3: Symbol in sg_model.py | C3: Value used | D3: Unit | E3: Tag | F3: Source IDs | G3: Note
A4: Sweep grid | B4: FREQS | C4: 1 kHz + 17.5 kHz·k, k = 0..199 | D4: Hz | E4: S | F4: S1, S2
A5: Series resistor | B5: Rs | C5: 10 | D5: kΩ | E5: S | F5: S3
A6: Inductor | B6: L | C6: 10 ±5% | D6: mH | E6: S | F6: S3
A7: Tank capacitor + node parasitics | B7: Ctank | C7: 100 ±5% + 2–7 | D7: pF | E7: S/E | F7: S3, S8 | G7: Parasitics part estimated
A8: Measurement noise | B8: NOISE | C8: 0.05 | D8: % of full scale | E8: E | F8: S1 (12-bit) | G8: S15 suggests up to ~3× higher with ESP32 ADC
A9: Inner electrode area | B9: el_area | C9: 2–4 | D9: cm² | E9: D | F9: - | G9: Design choice
A10: Skin per cm² | B10: y_skin | C10: G_DC 4.4 µS, G0 100 nS, C0 50 nF, m 0.75–0.85 | D10: per cm² | E10: S | F10: S6 | G10: S10 pending
A11: Skin hydration factor | B11: hyd | C11: 0.1–3 | D11: × | E11: S/E | F11: S1 (dry end) | G11: S10 pending
A12: Wrist-to-trunk tissue | B12: Rbody | C12: 100–400 + 100 | D12: Ω | E12: S | F12: S5, S1
A13: Watch ground to wrist (PCB) | B13: C_GB | C13: 3–13 | D13: pF | E13: G | F13: - | G13: 8–12 cm², 2–4 mm, εr 1.5–2.5
A14: Outer strap electrode to wrist | B14: C_GB (dual) | C14: +15–60 | D14: pF | E14: G | F14: - | G14: 20–30 cm², 1.5–3 mm, εr 2.5–3.5
A15: Driven-shield residual | B15: - | C15: 2–10 | D15: % | E15: E | F15: - | G15: S14 suggests 23–66%
A16: Body to surroundings, street shoes | B16: C_BE | C16: 110–170 | D16: pF | E16: S | F16: S4, S5
A17: Body to surroundings, barefoot | B17: C_BE | C17: 185–250 | D17: pF | E17: S | F17: S4
A18: Body to surroundings, sandals | B18: C_BE | C18: 130–210 | D18: pF | E18: E | F18: - | G18: Interpolated
A19: Body to surroundings, car seat | B19: C_BE | C19: 150–300 | D19: pF | E19: E | F19: -
A20: Walking change in C_BE | B20: - | C20: ±5 | D20: % | E20: S/E | F20: S4, S9 | G20: Direction sourced, size estimated
A21: Watch return path, single electrode | B21: C_GE | C21: 1.0–2.0 | D21: pF | E21: S/G | F21: S5, S8 | G21: S11 suggests ~0.45 pF at wrist
A22: Watch return path, with outer electrode | B22: C_GE | C22: 1.5–3.0 | D22: pF | E22: E | F22: S5
A23: Car body factor on return path | B23: - | C23: ×1.3–2 | D23: × | E23: E | F23: -
A24: Second person to surroundings | B24: C_AE | C24: 110–170 (+40–130 in car) | D24: pF | E24: S/E | F24: S4
A25: Hand contact area (grab) | B25: area | C25: 40–80 | D25: cm² | E25: E | F25: - | G25: S13 pending (hand 132–147 cm²)
A26: Clothing permittivity | B26: er | C26: 1.2–5.1 | D26: - | E26: S | F26: S7
A27: Clothing thickness | B27: t | C27: 0.16–0.58 per layer, 1–2 layers | D27: mm | E27: S/E | F27: S7
A28: Outer-electrode coating | B28: coat | C28: 25–100 µm, εr 3 | D28: - | E28: D | F28: - | G28: Design choice
A29: His palm on outer electrode | B29: Z_A0 | C29: skin 10–20 cm² + coating | D29: - | E29: E | F29: S6
A30: His hand near strap (forearm) | B30: Z_A0 | C30: 0.5–3 | D30: pF | E30: E | F30: -
A31: His body 0.3–0.6 m from watch | B31: Z_A0 | C31: 0.03–0.3 | D31: pF | E31: E | F31: -
A32: Bystander body-to-body | B32: Z_BA | C32: 2–15 | D32: pF | E32: E | F32: - | G32: S12 suggests > 21 pF
A33: Own hand: both arms | B33: r_arms | C33: 2 × 100–400 | D33: Ω | E33: S | F33: S5
A34: Railing grip area | B34: - | C34: 20–40 | D34: cm² | E34: E | F34: -
A35: Strap on metal pole | B35: - | C35: coating over 2–10 cm² | D35: - | E35: G | F35: -
A36: Phone self-capacitance | B36: - | C36: 4–12 | D36: pF | E36: G/E | F36: - | G36: 8·ε₀·r, r 6–10 cm
A37: Wooden table, bag | B37: - | C37: 1–20 | D37: pF | E37: E | F37: -
A38: Strap-gap jitter | B38: - | C38: 1.5 (normal) / 5 (strong) | D38: % | E38: E | F38: -

Sheet Still Estimated
A1: Values still estimated — measure these in Gate 1
A2: Priority 1 matters most for the results.
A3: Parameter | B3: Current value (v0.2) | C3: What the literature says | D3: How Gate 1 should measure it | E3: Priority
A4: Watch return path to surroundings (C_GE) | B4: 1.0–3.0 pF | C4: S11 gives ~0.45 pF at the wrist; S5 gives 1.5 pF | D4: Battery board on wrist: inject a known signal and compare with a reference capacitor (method in S5/S11) | E4: 1
A5: Driven-shield residual | B5: 2–10% | C5: S14 measured 23–66% for flat shields | D5: Measure watch-to-wrist coupling with the shield driven vs grounded | E5: 2
A6: His palm on the outer electrode | B6: Skin 10–20 cm² + coating | C6: No direct source | D6: Sweep change for firm grab vs light touch on the strap | E6: 3
A7: Measurement noise | B7: 0.05% of full scale | C7: S15 suggests ESP32 ADC may be ~3× noisier | D7: Log 1,000 sweeps with nothing touching; compute std. dev. per point | E7: 4
A8: Strap-gap jitter while walking | B8: 1.5–5% | C8: No source | D8: Log sweeps for 10 minutes of walking and arm movement | E8: 5
A9: His hand a few cm from the strap | B9: 0.5–3 pF | C9: No source | D9: Forearm-grab trials at 2, 5, 10 cm from the strap | E9: 6
A10: Bystander body-to-body coupling | B10: 2–15 pF | C10: S12: 21 pF at 1 m, so higher closer | D10: Read S12 Fig. 7(a) values below 1 m, or measure with two people | E10: 7
A11: Body capacitance in sandals / car seat | B11: 130–210 / 150–300 pF | C11: No measurement found | D11: Measure with an LCR meter at 1–100 kHz (Jonassen's method) | E11: 8
A12: Wrist on wooden table; bag | B12: 1–20 pF | C12: No source | D12: Record sweeps during these events | E12: 9
